Workbook

Sheet Andata
D1: 1^ GIORNATA | J1: 2^ GIORNATA | P1: 3^ GIORNATA | V1: 4^ GIORNATA
D2: 23 Agosto 2026 | J2: 30 Agosto 2026 | P2: 6 Settembre 2026 | V2: 13 Settembre 2026
D3: CASA | G3: OSPITE | J3: CASA | M3: OSPITE | P3: CASA | S3: OSPITE | V3: CASA | Y3: OSPITE
D4: Atalanta | G4: Sassuolo | J4: Atalanta | M4: Bologna | P4: Bologna | S4: Sassuolo | V4: Atalanta | Y4: Cagliari
D5: Bologna | G5: Lazio | J5: Cagliari | M5: Inter | P5: Cagliari | S5: Lecce | V5: Como | Y5: Parma
D6: Frosinone | G6: Juventus | J6: Fiorentina | M6: Frosinone | P6: Fiorentina | S6: Torino | V6: Genoa | Y6: Frosinone
D7: Genoa | G7: Napoli | J7: Juventus | M7: Parma | P7: Frosinone | S7: Venezia | V7: Inter | Y7: Udinese
D8: Inter | G8: Monza | J8: Lazio | M8: Genoa | P8: Genoa | S8: Como | V8: Lazio | Y8: Milan
D9: Parma | G9: Cagliari | J9: Lecce | M9: Roma | P9: Inter | S9: Napoli | V9: Lecce | Y9: Monza
D10: Roma | G10: Fiorentina | J10: Milan | M10: Venezia | P10: Juventus | S10: Milan | V10: Napoli | Y10: Bologna
D11: Torino | G11: Milan | J11: Monza | M11: Udinese | P11: Parma | S11: Monza | V11: Sassuolo | Y11: Juventus
D12: Udinese | G12: Como | J12: Napoli | M12: Como | P12: Roma | S12: Atalanta | V12: Torino | Y12: Roma
D13: Venezia | G13: Lecce | J13: Sassuolo | M13: Torino | P13: Udinese | S13: Lazio | V13: Venezia | Y13: Fiorentina
A15: 5^ GIORNATA | G15: 6^ GIORNATA | M15: 7^ GIORNATA | S15: 8^ GIORNATA | Y15: 9^ GIORNATA
A16: 20 Settembre 2026 | G16: 11 Ottobre 2026 | M16: 18 Ottobre 2026 | S16: 25 Ottobre 2026 | Y16: 28 Ottobre 2026
A17: CASA | D17: OSPITE | G17: CASA | J17: OSPITE | M17: CASA | P17: OSPITE | S17: CASA | V17: OSPITE | Y17: CASA | AB17: OSPITE
A18: Bologna | D18: Torino | G18: Atalanta | J18: Venezia | M18: Bologna | P18: Inter | S18: Atalanta | V18: Frosinone | Y18: Fiorentina | AB18: Atalanta
A19: Fiorentina | D19: Napoli | G19: Cagliari | J19: Juventus | M19: Fiorentina | P19: Como | S19: Cagliari | V19: Bologna | Y19: Frosinone | AB19: Lecce
A20: Frosinone | D20: Como | G20: Como | J20: Roma | M20: Frosinone | P20: Sassuolo | S20: Como | V20: Sassuolo | Y20: Genoa | AB20: Juventus
A21: Juventus | D21: Atalanta | G21: Genoa | J21: Fiorentina | M21: Juventus | P21: Lazio | S21: Genoa | V21: Venezia | Y21: Milan | AB21: Bologna
A22: Milan | D22: Lecce | G22: Inter | J22: Parma | M22: Milan | P22: Atalanta | S22: Inter | V22: Fiorentina | Y22: Monza | AB22: Napoli
A23: Monza | D23: Sassuolo | G23: Lazio | J23: Monza | M23: Monza | P23: Cagliari | S23: Lazio | V23: Parma | Y23: Parma | AB23: Udinese
A24: Parma | D24: Genoa | G24: Lecce | J24: Bologna | M24: Parma | P24: Torino | S24: Lecce | V24: Juventus | Y24: Roma | AB24: Cagliari
A25: Roma | D25: Inter | G25: Napoli | J25: Frosinone | M25: Roma | P25: Genoa | S25: Napoli | V25: Roma | Y25: Sassuolo | AB25: Lazio
A26: Udinese | D26: Cagliari | G26: Sassuolo | J26: Milan | M26: Udinese | P26: Lecce | S26: Torino | V26: Monza | Y26: Torino | AB26: Como
A27: Venezia | D27: Lazio | G27: Torino | J27: Udinese | M27: Venezia | P27: Napoli | S27: Udinese | V27: Milan | Y27: Venezia | AB27: Inter
A29: 10^ GIORNATA | G29: 11^ GIORNATA | M29: 12^ GIORNATA | S29: 13^ GIORNATA | Y29: 14^ GIORNATA
A30: 1 Novembre 2026 | G30: 8 Novembre 2026 | M30: 22 Novembre 2026 | S30: 29 Novembre 2026 | Y30: 6 Dicembre 2026
A31: CASA | D31: OSPITE | G31: CASA | J31: OSPITE | M31: CASA | P31: OSPITE | S31: CASA | V31: OSPITE | Y31: CASA | AB31: OSPITE
A32: Atalanta | D32: Parma | G32: Cagliari | J32: Frosinone | M32: Atalanta | P32: Inter | S32: Cagliari | V32: Milan | Y32: Bologna | AB32: Roma
A33: Bologna | D33: Monza | G33: Fiorentina | J33: Juventus | M33: Bologna | P33: Udinese | S33: Como | V33: Juventus | Y33: Fiorentina | AB33: Cagliari
A34: Como | D34: Venezia | G34: Genoa | J34: Milan | M34: Como | P34: Cagliari | S34: Frosinone | V34: Parma | Y34: Frosinone | AB34: Inter
A35: Frosinone | D35: Torino | G35: Inter | J35: Como | M35: Juventus | P35: Venezia | S35: Inter | V35: Genoa | Y35: Genoa | AB35: Torino
A36: Juventus | D36: Napoli | G36: Monza | J36: Atalanta | M36: Lazio | P36: Lecce | S36: Lecce | V36: Atalanta | Y36: Juventus | AB36: Udinese
A37: Lazio | D37: Cagliari | G37: Napoli | J37: Lazio | M37: Milan | P37: Frosinone | S37: Roma | V37: Monza | Y37: Lazio | AB37: Atalanta
A38: Lecce | D38: Genoa | G38: Parma | J38: Bologna | M38: Monza | P38: Fiorentina | S38: Sassuolo | V38: Napoli | Y38: Milan | AB38: Parma
A39: Milan | D39: Inter | G39: Roma | J39: Sassuolo | M39: Napoli | P39: Torino | S39: Torino | V39: Lazio | Y39: Monza | AB39: Como
A40: Sassuolo | D40: Fiorentina | G40: Torino | J40: Lecce | M40: Parma | P40: Roma | S40: Udinese | V40: Fiorentina | Y40: Napoli | AB40: Lecce
A41: Udinese | D41: Roma | G41: Venezia | J41: Udinese | M41: Sassuolo | P41: Genoa | S41: Venezia | V41: Bologna | Y41: Venezia | AB41: Sassuolo
A43: 15^ GIORNATA | G43: 16^ GIORNATA | M43: 17^ GIORNATA | S43: 18^ GIORNATA | Y43: 19^ GIORNATA
...

Sheet Ritorno
D1: 20^ GIORNATA | J1: 21^ GIORNATA | P1: 22^ GIORNATA | V1: 23^ GIORNATA
D2: 17 Gennaio 2027 | J2: 24 Gennaio 2027 | P2: 31 Gennaio 2027 | V2: 7 Febbraio 2027
D3: CASA | G3: OSPITE | J3: CASA | M3: OSPITE | P3: CASA | S3: OSPITE | V3: CASA | Y3: OSPITE
D4: Atalanta | G4: Roma | J4: Bologna | M4: Atalanta | P4: Atalanta | S4: Fiorentina | V4: Atalanta | Y4: Lazio
D5: Cagliari | G5: Como | J5: Como | M5: Napoli | P5: Cagliari | S5: Parma | V5: Bologna | Y5: Milan
D6: Juventus | G6: Genoa | J6: Fiorentina | M6: Sassuolo | P6: Genoa | S6: Lecce | V6: Como | Y6: Monza
D7: Lazio | G7: Bologna | J7: Frosinone | M7: Milan | P7: Lazio | S7: Venezia | V7: Fiorentina | Y7: Udinese
D8: Lecce | G8: Udinese | J8: Genoa | M8: Parma | P8: Milan | S8: Juventus | V8: Inter | Y8: Cagliari
D9: Milan | G9: Torino | J9: Inter | M9: Venezia | P9: Monza | S9: Roma | V9: Juventus | Y9: Sassuolo
D10: Napoli | G10: Fiorentina | J10: Juventus | M10: Cagliari | P10: Napoli | S10: Inter | V10: Lecce | Y10: Napoli
D11: Parma | G11: Inter | J11: Lecce | M11: Torino | P11: Sassuolo | S11: Como | V11: Parma | Y11: Frosinone
D12: Sassuolo | G12: Monza | J12: Monza | M12: Lazio | P12: Torino | S12: Frosinone | V12: Roma | Y12: Torino
D13: Venezia | G13: Frosinone | J13: Roma | M13: Udinese | P13: Udinese | S13: Bologna | V13: Venezia | Y13: Genoa
A15: 24^ GIORNATA | G15: 25^ GIORNATA | M15: 26^ GIORNATA | S15: 27^ GIORNATA | Y15: 28^ GIORNATA
A16: 14 Febbraio 2027 | G16: 21 Febbraio 2027 | M16: 28 Febbraio 2027 | S16: 7 Marzo 2027 | Y16: 14 Marzo 2027
A17: CASA | D17: OSPITE | G17: CASA | J17: OSPITE | M17: CASA | P17: OSPITE | S17: CASA | V17: OSPITE | Y17: CASA | AB17: OSPITE
A18: Bologna | D18: Como | G18: Atalanta | J18: Monza | M18: Bologna | P18: Lecce | S18: Atalanta | V18: Torino | Y18: Bologna | AB18: Napoli
A19: Cagliari | D19: Lazio | G19: Como | J19: Torino | M19: Cagliari | P19: Udinese | S19: Fiorentina | V19: Venezia | Y19: Cagliari | AB19: Fiorentina
A20: Frosinone | D20: Fiorentina | G20: Fiorentina | J20: Inter | M20: Como | P20: Milan | S20: Juventus | V20: Roma | Y20: Como | AB20: Udinese
A21: Genoa | D21: Atalanta | G21: Juventus | J21: Bologna | M21: Frosinone | P21: Napoli | S21: Lazio | V21: Frosinone | Y21: Frosinone | AB21: Monza
A22: Inter | D22: Milan | G22: Lazio | J22: Napoli | M22: Genoa | P22: Lazio | S22: Lecce | V22: Como | Y22: Genoa | AB22: Roma
A23: Monza | D23: Lecce | G23: Lecce | J23: Frosinone | M23: Inter | P23: Atalanta | S23: Milan | V23: Cagliari | Y23: Lazio | AB23: Juventus
A24: Napoli | D24: Juventus | G24: Milan | J24: Genoa | M24: Monza | P24: Juventus | S24: Monza | V24: Genoa | Y24: Milan | AB24: Sassuolo
A25: Roma | D25: Parma | G25: Sassuolo | J25: Roma | M25: Parma | P25: Sassuolo | S25: Napoli | V25: Parma | Y25: Parma | AB25: Lecce
A26: Torino | D26: Sassuolo | G26: Udinese | J26: Parma | M26: Roma | P26: Venezia | S26: Sassuolo | V26: Bologna | Y26: Torino | AB26: Inter
A27: Udinese | D27: Venezia | G27: Venezia | J27: Cagliari | M27: Torino | P27: Fiorentina | S27: Udinese | V27: Inter | Y27: Venezia | AB27: Atalanta
A29: 29^ GIORNATA | G29: 30^ GIORNATA | M29: 31^ GIORNATA | S29: 32^ GIORNATA | Y29: 33^ GIORNATA
A30: 21 Marzo 2027 | G30: 4 Aprile 2027 | M30: 11 Aprile 2027 | S30: 18 Aprile 2027 | Y30: 25 Aprile 2027
A31: CASA | D31: OSPITE | G31: CASA | J31: OSPITE | M31: CASA | P31: OSPITE | S31: CASA | V31: OSPITE | Y31: CASA | AB31: OSPITE
A32: Atalanta | D32: Milan | G32: Cagliari | J32: Napoli | M32: Bologna | P32: Venezia | S32: Atalanta | V32: Udinese | Y32: Cagliari | AB32: Monza
A33: Fiorentina | D33: Genoa | G33: Como | J33: Fiorentina | M33: Cagliari | P33: Atalanta | S33: Bologna | V33: Cagliari | Y33: Frosinone | AB33: Roma
A34: Inter | D34: Frosinone | G34: Frosinone | J34: Udinese | M34: Fiorentina | P34: Milan | S34: Como | V34: Frosinone | Y34: Genoa | AB34: Sassuolo
A35: Juventus | D35: Como | G35: Genoa | J35: Inter | M35: Frosinone | P35: Genoa | S35: Fiorentina | V35: Parma | Y35: Inter | AB35: Bologna
A36: Monza | D36: Bologna | G36: Lecce | J36: Lazio | M36: Inter | P36: Roma | S36: Milan | V36: Napoli | Y36: Juventus | AB36: Fiorentina
A37: Napoli | D37: Venezia | G37: Milan | J37: Monza | M37: Juventus | P37: Lecce | S37: Monza | V37: Inter | Y37: Lazio | AB37: Como
A38: Parma | D38: Lazio | G38: Roma | J38: Bologna | M38: Lazio | P38: Torino | S38: Roma | V38: Lazio | Y38: Lecce | AB38: Milan
A39: Roma | D39: Lecce | G39: Sassuolo | J39: Atalanta | M39: Napoli | P39: Sassuolo | S39: Sassuolo | V39: Lecce | Y39: Napoli | AB39: Udinese
A40: Sassuolo | D40: Cagliari | G40: Torino | J40: Juventus | M40: Parma | P40: Como | S40: Torino | V40: Genoa | Y40: Parma | AB40: Atalanta
A41: Udinese | D41: Torino | G41: Venezia | J41: Parma | M41: Udinese | P41: Monza | S41: Venezia | V41: Juventus | Y41: Venezia | AB41: Torino
A43: 34^ GIORNATA | G43: 35^ GIORNATA | M43: 36^ GIORNATA | S43: 37^ GIORNATA | Y43: 38^ GIORNATA
...

Sheet Classifica
A1: CLASSIFICA
A2: Nota: Questa classifica è calcolata sulla base dei pronostici effettuati
A3: Pos | B3: Squadra | C3: PG | D3: V | E3: N | F3: P | G3: GF | H3: GS | I3: DR | J3: Punti
A4: 1 | B4: =INDEX(Dati!$J$2:$J$21,$N4) -> Atalanta | C4: =INDEX(Dati!$K$2:$K$21,$N4) -> 0 | D4: =INDEX(Dati!$L$2:$L$21,$N4) -> 0 | E4: =INDEX(Dati!$M$2:$M$21,$N4) -> 0 | F4: =INDEX(Dati!$N$2:$N$21,$N4) -> 0 | G4: =INDEX(Dati!$O$2:$O$21,$N4) -> 0 | H4: =INDEX(Dati!$P$2:$P$21,$N4) -> 0 | I4: =INDEX(Dati!$Q$2:$Q$21,$N4) -> 0 | J4: =INDEX(Dati!$R$2:$R$21,$N4) -> 0 | M4: =LARGE(Dati!$S$2:$S$21,A4) -> 100000019 | N4: =MATCH(M4,Dati!$S$2:$S$21,0) -> 1
A5: 2 | B5: =INDEX(Dati!$J$2:$J$21,$N5) -> Bologna | C5: =INDEX(Dati!$K$2:$K$21,$N5) -> 0 | D5: =INDEX(Dati!$L$2:$L$21,$N5) -> 0 | E5: =INDEX(Dati!$M$2:$M$21,$N5) -> 0 | F5: =INDEX(Dati!$N$2:$N$21,$N5) -> 0 | G5: =INDEX(Dati!$O$2:$O$21,$N5) -> 0 | H5: =INDEX(Dati!$P$2:$P$21,$N5) -> 0 | I5: =INDEX(Dati!$Q$2:$Q$21,$N5) -> 0 | J5: =INDEX(Dati!$R$2:$R$21,$N5) -> 0 | M5: =LARGE(Dati!$S$2:$S$21,A5) -> 100000018 | N5: =MATCH(M5,Dati!$S$2:$S$21,0) -> 2
A6: 3 | B6: =INDEX(Dati!$J$2:$J$21,$N6) -> Cagliari | C6: =INDEX(Dati!$K$2:$K$21,$N6) -> 0 | D6: =INDEX(Dati!$L$2:$L$21,$N6) -> 0 | E6: =INDEX(Dati!$M$2:$M$21,$N6) -> 0 | F6: =INDEX(Dati!$N$2:$N$21,$N6) -> 0 | G6: =INDEX(Dati!$O$2:$O$21,$N6) -> 0 | H6: =INDEX(Dati!$P$2:$P$21,$N6) -> 0 | I6: =INDEX(Dati!$Q$2:$Q$21,$N6) -> 0 | J6: =INDEX(Dati!$R$2:$R$21,$N6) -> 0 | M6: =LARGE(Dati!$S$2:$S$21,A6) -> 100000017 | N6: =MATCH(M6,Dati!$S$2:$S$21,0) -> 3
A7: 4 | B7: =INDEX(Dati!$J$2:$J$21,$N7) -> Como | C7: =INDEX(Dati!$K$2:$K$21,$N7) -> 0 | D7: =INDEX(Dati!$L$2:$L$21,$N7) -> 0 | E7: =INDEX(Dati!$M$2:$M$21,$N7) -> 0 | F7: =INDEX(Dati!$N$2:$N$21,$N7) -> 0 | G7: =INDEX(Dati!$O$2:$O$21,$N7) -> 0 | H7: =INDEX(Dati!$P$2:$P$21,$N7) -> 0 | I7: =INDEX(Dati!$Q$2:$Q$21,$N7) -> 0 | J7: =INDEX(Dati!$R$2:$R$21,$N7) -> 0 | M7: =LARGE(Dati!$S$2:$S$21,A7) -> 100000016 | N7: =MATCH(M7,Dati!$S$2:$S$21,0) -> 4
A8: 5 | B8: =INDEX(Dati!$J$2:$J$21,$N8) -> Fiorentina | C8: =INDEX(Dati!$K$2:$K$21,$N8) -> 0 | D8: =INDEX(Dati!$L$2:$L$21,$N8) -> 0 | E8: =INDEX(Dati!$M$2:$M$21,$N8) -> 0 | F8: =INDEX(Dati!$N$2:$N$21,$N8) -> 0 | G8: =INDEX(Dati!$O$2:$O$21,$N8) -> 0 | H8: =INDEX(Dati!$P$2:$P$21,$N8) -> 0 | I8: =INDEX(Dati!$Q$2:$Q$21,$N8) -> 0 | J8: =INDEX(Dati!$R$2:$R$21,$N8) -> 0 | M8: =LARGE(Dati!$S$2:$S$21,A8) -> 100000015 | N8: =MATCH(M8,Dati!$S$2:$S$21,0) -> 5
A9: 6 | B9: =INDEX(Dati!$J$2:$J$21,$N9) -> Frosinone | C9: =INDEX(Dati!$K$2:$K$21,$N9) -> 0 | D9: =INDEX(Dati!$L$2:$L$21,$N9) -> 0 | E9: =INDEX(Dati!$M$2:$M$21,$N9) -> 0 | F9: =INDEX(Dati!$N$2:$N$21,$N9) -> 0 | G9: =INDEX(Dati!$O$2:$O$21,$N9) -> 0 | H9: =INDEX(Dati!$P$2:$P$21,$N9) -> 0 | I9: =INDEX(Dati!$Q$2:$Q$21,$N9) -> 0 | J9: =INDEX(Dati!$R$2:$R$21,$N9) -> 0 | M9: =LARGE(Dati!$S$2:$S$21,A9) -> 100000014 | N9: =MATCH(M9,Dati!$S$2:$S$21,0) -> 6
A10: 7 | B10: =INDEX(Dati!$J$2:$J$21,$N10) -> Genoa | C10: =INDEX(Dati!$K$2:$K$21,$N10) -> 0 | D10: =INDEX(Dati!$L$2:$L$21,$N10) -> 0 | E10: =INDEX(Dati!$M$2:$M$21,$N10) -> 0 | F10: =INDEX(Dati!$N$2:$N$21,$N10) -> 0 | G10: =INDEX(Dati!$O$2:$O$21,$N10) -> 0 | H10: =INDEX(Dati!$P$2:$P$21,$N10) -> 0 | I10: =INDEX(Dati!$Q$2:$Q$21,$N10) -> 0 | J10: =INDEX(Dati!$R$2:$R$21,$N10) -> 0 | M10: =LARGE(Dati!$S$2:$S$21,A10) -> 100000013 | N10: =MATCH(M10,Dati!$S$2:$S$21,0) -> 7
A11: 8 | B11: =INDEX(Dati!$J$2:$J$21,$N11) -> Inter | C11: =INDEX(Dati!$K$2:$K$21,$N11) -> 0 | D11: =INDEX(Dati!$L$2:$L$21,$N11) -> 0 | E11: =INDEX(Dati!$M$2:$M$21,$N11) -> 0 | F11: =INDEX(Dati!$N$2:$N$21,$N11) -> 0 | G11: =INDEX(Dati!$O$2:$O$21,$N11) -> 0 | H11: =INDEX(Dati!$P$2:$P$21,$N11) -> 0 | I11: =INDEX(Dati!$Q$2:$Q$21,$N11) -> 0 | J11: =INDEX(Dati!$R$2:$R$21,$N11) -> 0 | M11: =LARGE(Dati!$S$2:$S$21,A11) -> 100000012 | N11: =MATCH(M11,Dati!$S$2:$S$21,0) -> 8
A12: 9 | B12: =INDEX(Dati!$J$2:$J$21,$N12) -> Juventus | C12: =INDEX(Dati!$K$2:$K$21,$N12) -> 0 | D12: =INDEX(Dati!$L$2:$L$21,$N12) -> 0 | E12: =INDEX(Dati!$M$2:$M$21,$N12) -> 0 | F12: =INDEX(Dati!$N$2:$N$21,$N12) -> 0 | G12: =INDEX(Dati!$O$2:$O$21,$N12) -> 0 | H12: =INDEX(Dati!$P$2:$P$21,$N12) -> 0 | I12: =INDEX(Dati!$Q$2:$Q$21,$N12) -> 0 | J12: =INDEX(Dati!$R$2:$R$21,$N12) -> 0 | M12: =LARGE(Dati!$S$2:$S$21,A12) -> 100000011 | N12: =MATCH(M12,Dati!$S$2:$S$21,0) -> 9
A13: 10 | B13: =INDEX(Dati!$J$2:$J$21,$N13) -> Lazio | C13: =INDEX(Dati!$K$2:$K$21,$N13) -> 0 | D13: =INDEX(Dati!$L$2:$L$21,$N13) -> 0 | E13: =INDEX(Dati!$M$2:$M$21,$N13) -> 0 | F13: =INDEX(Dati!$N$2:$N$21,$N13) -> 0 | G13: =INDEX(Dati!$O$2:$O$21,$N13) -> 0 | H13: =INDEX(Dati!$P$2:$P$21,$N13) -> 0 | I13: =INDEX(Dati!$Q$2:$Q$21,$N13) -> 0 | J13: =INDEX(Dati!$R$2:$R$21,$N13) -> 0 | M13: =LARGE(Dati!$S$2:$S$21,A13) -> 100000010 | N13: =MATCH(M13,Dati!$S$2:$S$21,0) -> 10
A14: 11 | B14: =INDEX(Dati!$J$2:$J$21,$N14) -> Lecce | C14: =INDEX(Dati!$K$2:$K$21,$N14) -> 0 | D14: =INDEX(Dati!$L$2:$L$21,$N14) -> 0 | E14: =INDEX(Dati!$M$2:$M$21,$N14) -> 0 | F14: =INDEX(Dati!$N$2:$N$21,$N14) -> 0 | G14: =INDEX(Dati!$O$2:$O$21,$N14) -> 0 | H14: =INDEX(Dati!$P$2:$P$21,$N14) -> 0 | I14: =INDEX(Dati!$Q$2:$Q$21,$N14) -> 0 | J14: =INDEX(Dati!$R$2:$R$21,$N14) -> 0 | M14: =LARGE(Dati!$S$2:$S$21,A14) -> 100000009 | N14: =MATCH(M14,Dati!$S$2:$S$21,0) -> 11
A15: 12 | B15: =INDEX(Dati!$J$2:$J$21,$N15) -> Milan | C15: =INDEX(Dati!$K$2:$K$21,$N15) -> 0 | D15: =INDEX(Dati!$L$2:$L$21,$N15) -> 0 | E15: =INDEX(Dati!$M$2:$M$21,$N15) -> 0 | F15: =INDEX(Dati!$N$2:$N$21,$N15) -> 0 | G15: =INDEX(Dati!$O$2:$O$21,$N15) -> 0 | H15: =INDEX(Dati!$P$2:$P$21,$N15) -> 0 | I15: =INDEX(Dati!$Q$2:$Q$21,$N15) -> 0 | J15: =INDEX(Dati!$R$2:$R$21,$N15) -> 0 | M15: =LARGE(Dati!$S$2:$S$21,A15) -> 100000008 | N15: =MATCH(M15,Dati!$S$2:$S$21,0) -> 12
... A23: 20 | B23: =INDEX(Dati!$J$2:$J$21,$N23) -> Venezia | C23: =INDEX(Dati!$K$2:$K$21,$N23) -> 0 | D23: =INDEX(Dati!$L$2:$L$21,$N23) -> 0 | E23: =INDEX(Dati!$M$2:$M$21,$N23) -> 0 | F23: =INDEX(Dati!$N$2:$N$21,$N23) -> 0 | G23: =INDEX(Dati!$O$2:$O$21,$N23) -> 0 | H23: =INDEX(Dati!$P$2:$P$21,$N23) -> 0 | I23: =INDEX(Dati!$Q$2:$Q$21,$N23) -> 0 | J23: =INDEX(Dati!$R$2:$R$21,$N23) -> 0 | M23: =LARGE(Dati!$S$2:$S$21,A23) -> 100000000 | N23: =MATCH(M23,Dati!$S$2:$S$21,0) -> 20

Sheet Dati
A1: Home | B1: HG | C1: AG | D1: Away | E1: HP | F1: AP | G1: Played | J1: Squadra | K1: PG | L1: V | M1: N | N1: P | O1: GF | P1: GS | Q1: DR | R1: Punti | S1: Key | T1: PuntiAnd | U1: DRand | V1: GFand | W1: KeyAnd
A2: =Andata!D4 -> Atalanta | B2: =IF(Andata!E4="","",Andata!E4) | C2: =IF(Andata!F4="","",Andata!F4) | D2: =Andata!G4 -> Sassuolo | E2: =IF(OR(B2="",C2=""),"",IF(B2>C2,3,IF(B2=C2,1,0))) | F2: =IF(OR(B2="",C2=""),"",IF(C2>B2,3,IF(B2=C2,1,0))) | G2: =IF(OR(B2="",C2=""),0,1) -> 0 | J2: Atalanta | K2: =SUMIFS($G$2:$G$381,$A$2:$A$381,J2)+SUMIFS($G$2:$G$381,$D$2:$D$381,J2) -> 0 | L2: =COUNTIFS($A$2:$A$381,J2,$E$2:$E$381,3)+COUNTIFS($D$2:$D$381,J2,$F$2:$F$381,3) -> 0 | M2: =COUNTIFS($A$2:$A$381,J2,$E$2:$E$381,1)+COUNTIFS($D$2:$D$381,J2,$F$2:$F$381,1) -> 0 | N2: =COUNTIFS($A$2:$A$381,J2,$E$2:$E$381,0)+COUNTIFS($D$2:$D$381,J2,$F$2:$F$381,0) -> 0 | O2: =SUMIFS($B$2:$B$381,$A$2:$A$381,J2)+SUMIFS($C$2:$C$381,$D$2:$D$381,J2) -> 0 | P2: =SUMIFS($C$2:$C$381,$A$2:$A$381,J2)+SUMIFS($B$2:$B$381,$D$2:$D$381,J2) -> 0 | Q2: =O2-P2 -> 0 | R2: =L2*3+M2 -> 0 | S2: =R2*1000000000+(Q2+1000)*100000+O2*100+19 -> 100000019 | T2: =(COUNTIFS($A$2:$A$191,J2,$E$2:$E$191,3)+COUNTIFS($D$2:$D$191,J2,$F$2:$F$191,3))*3+(COUNTIFS($A$2:$A$191,J2,$E$2:$E$191,1)+COUNTIFS($D$2:$D$191,J2,$F$2:$F$191,1)) -> 0 | U2: =(SUMIFS($B$2:$B$191,$A$2:$A$191,J2)+SUMIFS($C$2:$C$191,$D$2:$D$191,J2))-(SUMIFS($C$2:$C$191,$A$2:$A$191,J2)+SUMIFS($B$2:$B$191,$D$2:$D$191,J2)) -> 0 | V2: =SUMIFS($B$2:$B$191,$A$2:$A$191,J2)+SUMIFS($C$2:$C$191,$D$2:$D$191,J2) -> 0 | W2: =T2*1000000000+(U2+1000)*100000+V2*100+19 -> 100000019
A3: =Andata!D5 -> Bologna | B3: =IF(Andata!E5="","",Andata!E5) | C3: =IF(Andata!F5="","",Andata!F5) | D3: =Andata!G5 -> Lazio | E3: =IF(OR(B3="",C3=""),"",IF(B3>C3,3,IF(B3=C3,1,0))) | F3: =IF(OR(B3="",C3=""),"",IF(C3>B3,3,IF(B3=C3,1,0))) | G3: =IF(OR(B3="",C3=""),0,1) -> 0 | J3: Bologna | K3: =SUMIFS($G$2:$G$381,$A$2:$A$381,J3)+SUMIFS($G$2:$G$381,$D$2:$D$381,J3) -> 0 | L3: =COUNTIFS($A$2:$A$381,J3,$E$2:$E$381,3)+COUNTIFS($D$2:$D$381,J3,$F$2:$F$381,3) -> 0 | M3: =COUNTIFS($A$2:$A$381,J3,$E$2:$E$381,1)+COUNTIFS($D$2:$D$381,J3,$F$2:$F$381,1) -> 0 | N3: =COUNTIFS($A$2:$A$381,J3,$E$2:$E$381,0)+COUNTIFS($D$2:$D$381,J3,$F$2:$F$381,0) -> 0 | O3: =SUMIFS($B$2:$B$381,$A$2:$A$381,J3)+SUMIFS($C$2:$C$381,$D$2:$D$381,J3) -> 0 | P3: =SUMIFS($C$2:$C$381,$A$2:$A$381,J3)+SUMIFS($B$2:$B$381,$D$2:$D$381,J3) -> 0 | Q3: =O3-P3 -> 0 | R3: =L3*3+M3 -> 0 | S3: =R3*1000000000+(Q3+1000)*100000+O3*100+18 -> 100000018 | T3: =(COUNTIFS($A$2:$A$191,J3,$E$2:$E$191,3)+COUNTIFS($D$2:$D$191,J3,$F$2:$F$191,3))*3+(COUNTIFS($A$2:$A$191,J3,$E$2:$E$191,1)+COUNTIFS($D$2:$D$191,J3,$F$2:$F$191,1)) -> 0 | U3: =(SUMIFS($B$2:$B$191,$A$2:$A$191,J3)+SUMIFS($C$2:$C$191,$D$2:$D$191,J3))-(SUMIFS($C$2:$C$191,$A$2:$A$191,J3)+SUMIFS($B$2:$B$191,$D$2:$D$191,J3)) -> 0 | V3: =SUMIFS($B$2:$B$191,$A$2:$A$191,J3)+SUMIFS($C$2:$C$191,$D$2:$D$191,J3) -> 0 | W3: =T3*1000000000+(U3+1000)*100000+V3*100+18 -> 100000018
A4: =Andata!D6 -> Frosinone | B4: =IF(Andata!E6="","",Andata!E6) | C4: =IF(Andata!F6="","",Andata!F6) | D4: =Andata!G6 -> Juventus | E4: =IF(OR(B4="",C4=""),"",IF(B4>C4,3,IF(B4=C4,1,0))) | F4: =IF(OR(B4="",C4=""),"",IF(C4>B4,3,IF(B4=C4,1,0))) | G4: =IF(OR(B4="",C4=""),0,1) -> 0 | J4: Cagliari | K4: =SUMIFS($G$2:$G$381,$A$2:$A$381,J4)+SUMIFS($G$2:$G$381,$D$2:$D$381,J4) -> 0 | L4: =COUNTIFS($A$2:$A$381,J4,$E$2:$E$381,3)+COUNTIFS($D$2:$D$381,J4,$F$2:$F$381,3) -> 0 | M4: =COUNTIFS($A$2:$A$381,J4,$E$2:$E$381,1)+COUNTIFS($D$2:$D$381,J4,$F$2:$F$381,1) -> 0 | N4: =COUNTIFS($A$2:$A$381,J4,$E$2:$E$381,0)+COUNTIFS($D$2:$D$381,J4,$F$2:$F$381,0) -> 0 | O4: =SUMIFS($B$2:$B$381,$A$2:$A$381,J4)+SUMIFS($C$2:$C$381,$D$2:$D$381,J4) -> 0 | P4: =SUMIFS($C$2:$C$381,$A$2:$A$381,J4)+SUMIFS($B$2:$B$381,$D$2:$D$381,J4) -> 0 | Q4: =O4-P4 -> 0 | R4: =L4*3+M4 -> 0 | S4: =R4*1000000000+(Q4+1000)*100000+O4*100+17 -> 100000017 | T4: =(COUNTIFS($A$2:$A$191,J4,$E$2:$E$191,3)+COUNTIFS($D$2:$D$191,J4,$F$2:$F$191,3))*3+(COUNTIFS($A$2:$A$191,J4,$E$2:$E$191,1)+COUNTIFS($D$2:$D$191,J4,$F$2:$F$191,1)) -> 0 | U4: =(SUMIFS($B$2:$B$191,$A$2:$A$191,J4)+SUMIFS($C$2:$C$191,$D$2:$D$191,J4))-(SUMIFS($C$2:$C$191,$A$2:$A$191,J4)+SUMIFS($B$2:$B$191,$D$2:$D$191,J4)) -> 0 | V4: =SUMIFS($B$2:$B$191,$A$2:$A$191,J4)+SUMIFS($C$2:$C$191,$D$2:$D$191,J4) -> 0 | W4: =T4*1000000000+(U4+1000)*100000+V4*100+17 -> 100000017
A5: =Andata!D7 -> Genoa | B5: =IF(Andata!E7="","",Andata!E7) | C5: =IF(Andata!F7="","",Andata!F7) | D5: =Andata!G7 -> Napoli | E5: =IF(OR(B5="",C5=""),"",IF(B5>C5,3,IF(B5=C5,1,0))) | F5: =IF(OR(B5="",C5=""),"",IF(C5>B5,3,IF(B5=C5,1,0))) | G5: =IF(OR(B5="",C5=""),0,1) -> 0 | J5: Como | K5: =SUMIFS($G$2:$G$381,$A$2:$A$381,J5)+SUMIFS($G$2:$G$381,$D$2:$D$381,J5) -> 0 | L5: =COUNTIFS($A$2:$A$381,J5,$E$2:$E$381,3)+COUNTIFS($D$2:$D$381,J5,$F$2:$F$381,3) -> 0 | M5: =COUNTIFS($A$2:$A$381,J5,$E$2:$E$381,1)+COUNTIFS($D$2:$D$381,J5,$F$2:$F$381,1) -> 0 | N5: =COUNTIFS($A$2:$A$381,J5,$E$2:$E$381,0)+COUNTIFS($D$2:$D$381,J5,$F$2:$F$381,0) -> 0 | O5: =SUMIFS($B$2:$B$381,$A$2:$A$381,J5)+SUMIFS($C$2:$C$381,$D$2:$D$381,J5) -> 0 | P5: =SUMIFS($C$2:$C$381,$A$2:$A$381,J5)+SUMIFS($B$2:$B$381,$D$2:$D$381,J5) -> 0 | Q5: =O5-P5 -> 0 | R5: =L5*3+M5 -> 0 | S5: =R5*1000000000+(Q5+1000)*100000+O5*100+16 -> 100000016 | T5: =(COUNTIFS($A$2:$A$191,J5,$E$2:$E$191,3)+COUNTIFS($D$2:$D$191,J5,$F$2:$F$191,3))*3+(COUNTIFS($A$2:$A$191,J5,$E$2:$E$191,1)+COUNTIFS($D$2:$D$191,J5,$F$2:$F$191,1)) -> 0 | U5: =(SUMIFS($B$2:$B$191,$A$2:$A$191,J5)+SUMIFS($C$2:$C$191,$D$2:$D$191,J5))-(SUMIFS($C$2:$C$191,$A$2:$A$191,J5)+SUMIFS($B$2:$B$191,$D$2:$D$191,J5)) -> 0 | V5: =SUMIFS($B$2:$B$191,$A$2:$A$191,J5)+SUMIFS($C$2:$C$191,$D$2:$D$191,J5) -> 0 | W5: =T5*1000000000+(U5+1000)*100000+V5*100+16 -> 100000016
A6: =Andata!D8 -> Inter | B6: =IF(Andata!E8="","",Andata!E8) | C6: =IF(Andata!F8="","",Andata!F8) | D6: =Andata!G8 -> Monza | E6: =IF(OR(B6="",C6=""),"",IF(B6>C6,3,IF(B6=C6,1,0))) | F6: =IF(OR(B6="",C6=""),"",IF(C6>B6,3,IF(B6=C6,1,0))) | G6: =IF(OR(B6="",C6=""),0,1) -> 0 | J6: Fiorentina | K6: =SUMIFS($G$2:$G$381,$A$2:$A$381,J6)+SUMIFS($G$2:$G$381,$D$2:$D$381,J6) -> 0 | L6: =COUNTIFS($A$2:$A$381,J6,$E$2:$E$381,3)+COUNTIFS($D$2:$D$381,J6,$F$2:$F$381,3) -> 0 | M6: =COUNTIFS($A$2:$A$381,J6,$E$2:$E$381,1)+COUNTIFS($D$2:$D$381,J6,$F$2:$F$381,1) -> 0 | N6: =COUNTIFS($A$2:$A$381,J6,$E$2:$E$381,0)+COUNTIFS($D$2:$D$381,J6,$F$2:$F$381,0) -> 0 | O6: =SUMIFS($B$2:$B$381,$A$2:$A$381,J6)+SUMIFS($C$2:$C$381,$D$2:$D$381,J6) -> 0 | P6: =SUMIFS($C$2:$C$381,$A$2:$A$381,J6)+SUMIFS($B$2:$B$381,$D$2:$D$381,J6) -> 0 | Q6: =O6-P6 -> 0 | R6: =L6*3+M6 -> 0 | S6: =R6*1000000000+(Q6+1000)*100000+O6*100+15 -> 100000015 | T6: =(COUNTIFS($A$2:$A$191,J6,$E$2:$E$191,3)+COUNTIFS($D$2:$D$191,J6,$F$2:$F$191,3))*3+(COUNTIFS($A$2:$A$191,J6,$E$2:$E$191,1)+COUNTIFS($D$2:$D$191,J6,$F$2:$F$191,1)) -> 0 | U6: =(SUMIFS($B$2:$B$191,$A$2:$A$191,J6)+SUMIFS($C$2:$C$191,$D$2:$D$191,J6))-(SUMIFS($C$2:$C$191,$A$2:$A$191,J6)+SUMIFS($B$2:$B$191,$D$2:$D$191,J6)) -> 0 | V6: =SUMIFS($B$2:$B$191,$A$2:$A$191,J6)+SUMIFS($C$2:$C$191,$D$2:$D$191,J6) -> 0 | W6: =T6*1000000000+(U6+1000)*100000+V6*100+15 -> 100000015
A7: =Andata!D9 -> Parma | B7: =IF(Andata!E9="","",Andata!E9) | C7: =IF(Andata!F9="","",Andata!F9) | D7: =Andata!G9 -> Cagliari | E7: =IF(OR(B7="",C7=""),"",IF(B7>C7,3,IF(B7=C7,1,0))) | F7: =IF(OR(B7="",C7=""),"",IF(C7>B7,3,IF(B7=C7,1,0))) | G7: =IF(OR(B7="",C7=""),0,1) -> 0 | J7: Frosinone | K7: =SUMIFS($G$2:$G$381,$A$2:$A$381,J7)+SUMIFS($G$2:$G$381,$D$2:$D$381,J7) -> 0 | L7: =COUNTIFS($A$2:$A$381,J7,$E$2:$E$381,3)+COUNTIFS($D$2:$D$381,J7,$F$2:$F$381,3) -> 0 | M7: =COUNTIFS($A$2:$A$381,J7,$E$2:$E$381,1)+COUNTIFS($D$2:$D$381,J7,$F$2:$F$381,1) -> 0 | N7: =COUNTIFS($A$2:$A$381,J7,$E$2:$E$381,0)+COUNTIFS($D$2:$D$381,J7,$F$2:$F$381,0) -> 0 | O7: =SUMIFS($B$2:$B$381,$A$2:$A$381,J7)+SUMIFS($C$2:$C$381,$D$2:$D$381,J7) -> 0 | P7: =SUMIFS($C$2:$C$381,$A$2:$A$381,J7)+SUMIFS($B$2:$B$381,$D$2:$D$381,J7) -> 0 | Q7: =O7-P7 -> 0 | R7: =L7*3+M7 -> 0 | S7: =R7*1000000000+(Q7+1000)*100000+O7*100+14 -> 100000014 | T7: =(COUNTIFS($A$2:$A$191,J7,$E$2:$E$191,3)+COUNTIFS($D$2:$D$191,J7,$F$2:$F$191,3))*3+(COUNTIFS($A$2:$A$191,J7,$E$2:$E$191,1)+COUNTIFS($D$2:$D$191,J7,$F$2:$F$191,1)) -> 0 | U7: =(SUMIFS($B$2:$B$191,$A$2:$A$191,J7)+SUMIFS($C$2:$C$191,$D$2:$D$191,J7))-(SUMIFS($C$2:$C$191,$A$2:$A$191,J7)+SUMIFS($B$2:$B$191,$D$2:$D$191,J7)) -> 0 | V7: =SUMIFS($B$2:$B$191,$A$2:$A$191,J7)+SUMIFS($C$2:$C$191,$D$2:$D$191,J7) -> 0 | W7: =T7*1000000000+(U7+1000)*100000+V7*100+14 -> 100000014
A8: =Andata!D10 -> Roma | B8: =IF(Andata!E10="","",Andata!E10) | C8: =IF(Andata!F10="","",Andata!F10) | D8: =Andata!G10 -> Fiorentina | E8: =IF(OR(B8="",C8=""),"",IF(B8>C8,3,IF(B8=C8,1,0))) | F8: =IF(OR(B8="",C8=""),"",IF(C8>B8,3,IF(B8=C8,1,0))) | G8: =IF(OR(B8="",C8=""),0,1) -> 0 | J8: Genoa | K8: =SUMIFS($G$2:$G$381,$A$2:$A$381,J8)+SUMIFS($G$2:$G$381,$D$2:$D$381,J8) -> 0 | L8: =COUNTIFS($A$2:$A$381,J8,$E$2:$E$381,3)+COUNTIFS($D$2:$D$381,J8,$F$2:$F$381,3) -> 0 | M8: =COUNTIFS($A$2:$A$381,J8,$E$2:$E$381,1)+COUNTIFS($D$2:$D$381,J8,$F$2:$F$381,1) -> 0 | N8: =COUNTIFS($A$2:$A$381,J8,$E$2:$E$381,0)+COUNTIFS($D$2:$D$381,J8,$F$2:$F$381,0) -> 0 | O8: =SUMIFS($B$2:$B$381,$A$2:$A$381,J8)+SUMIFS($C$2:$C$381,$D$2:$D$381,J8) -> 0 | P8: =SUMIFS($C$2:$C$381,$A$2:$A$381,J8)+SUMIFS($B$2:$B$381,$D$2:$D$381,J8) -> 0 | Q8: =O8-P8 -> 0 | R8: =L8*3+M8 -> 0 | S8: =R8*1000000000+(Q8+1000)*100000+O8*100+13 -> 100000013 | T8: =(COUNTIFS($A$2:$A$191,J8,$E$2:$E$191,3)+COUNTIFS($D$2:$D$191,J8,$F$2:$F$191,3))*3+(COUNTIFS($A$2:$A$191,J8,$E$2:$E$191,1)+COUNTIFS($D$2:$D$191,J8,$F$2:$F$191,1)) -> 0 | U8: =(SUMIFS($B$2:$B$191,$A$2:$A$191,J8)+SUMIFS($C$2:$C$191,$D$2:$D$191,J8))-(SUMIFS($C$2:$C$191,$A$2:$A$191,J8)+SUMIFS($B$2:$B$191,$D$2:$D$191,J8)) -> 0 | V8: =SUMIFS($B$2:$B$191,$A$2:$A$191,J8)+SUMIFS($C$2:$C$191,$D$2:$D$191,J8) -> 0 | W8: =T8*1000000000+(U8+1000)*100000+V8*100+13 -> 100000013
A9: =Andata!D11 -> Torino | B9: =IF(Andata!E11="","",Andata!E11) | C9: =IF(Andata!F11="","",Andata!F11) | D9: =Andata!G11 -> Milan | E9: =IF(OR(B9="",C9=""),"",IF(B9>C9,3,IF(B9=C9,1,0))) | F9: =IF(OR(B9="",C9=""),"",IF(C9>B9,3,IF(B9=C9,1,0))) | G9: =IF(OR(B9="",C9=""),0,1) -> 0 | J9: Inter | K9: =SUMIFS($G$2:$G$381,$A$2:$A$381,J9)+SUMIFS($G$2:$G$381,$D$2:$D$381,J9) -> 0 | L9: =COUNTIFS($A$2:$A$381,J9,$E$2:$E$381,3)+COUNTIFS($D$2:$D$381,J9,$F$2:$F$381,3) -> 0 | M9: =COUNTIFS($A$2:$A$381,J9,$E$2:$E$381,1)+COUNTIFS($D$2:$D$381,J9,$F$2:$F$381,1) -> 0 | N9: =COUNTIFS($A$2:$A$381,J9,$E$2:$E$381,0)+COUNTIFS($D$2:$D$381,J9,$F$2:$F$381,0) -> 0 | O9: =SUMIFS($B$2:$B$381,$A$2:$A$381,J9)+SUMIFS($C$2:$C$381,$D$2:$D$381,J9) -> 0 | P9: =SUMIFS($C$2:$C$381,$A$2:$A$381,J9)+SUMIFS($B$2:$B$381,$D$2:$D$381,J9) -> 0 | Q9: =O9-P9 -> 0 | R9: =L9*3+M9 -> 0 | S9: =R9*1000000000+(Q9+1000)*100000+O9*100+12 -> 100000012 | T9: =(COUNTIFS($A$2:$A$191,J9,$E$2:$E$191,3)+COUNTIFS($D$2:$D$191,J9,$F$2:$F$191,3))*3+(COUNTIFS($A$2:$A$191,J9,$E$2:$E$191,1)+COUNTIFS($D$2:$D$191,J9,$F$2:$F$191,1)) -> 0 | U9: =(SUMIFS($B$2:$B$191,$A$2:$A$191,J9)+SUMIFS($C$2:$C$191,$D$2:$D$191,J9))-(SUMIFS($C$2:$C$191,$A$2:$A$191,J9)+SUMIFS($B$2:$B$191,$D$2:$D$191,J9)) -> 0 | V9: =SUMIFS($B$2:$B$191,$A$2:$A$191,J9)+SUMIFS($C$2:$C$191,$D$2:$D$191,J9) -> 0 | W9: =T9*1000000000+(U9+1000)*100000+V9*100+12 -> 100000012
A10: =Andata!D12 -> Udinese | B10: =IF(Andata!E12="","",Andata!E12) | C10: =IF(Andata!F12="","",Andata!F12) | D10: =Andata!G12 -> Como | E10: =IF(OR(B10="",C10=""),"",IF(B10>C10,3,IF(B10=C10,1,0))) | F10: =IF(OR(B10="",C10=""),"",IF(C10>B10,3,IF(B10=C10,1,0))) | G10: =IF(OR(B10="",C10=""),0,1) -> 0 | J10: Juventus | K10: =SUMIFS($G$2:$G$381,$A$2:$A$381,J10)+SUMIFS($G$2:$G$381,$D$2:$D$381,J10) -> 0 | L10: =COUNTIFS($A$2:$A$381,J10,$E$2:$E$381,3)+COUNTIFS($D$2:$D$381,J10,$F$2:$F$381,3) -> 0 | M10: =COUNTIFS($A$2:$A$381,J10,$E$2:$E$381,1)+COUNTIFS($D$2:$D$381,J10,$F$2:$F$381,1) -> 0 | N10: =COUNTIFS($A$2:$A$381,J10,$E$2:$E$381,0)+COUNTIFS($D$2:$D$381,J10,$F$2:$F$381,0) -> 0 | O10: =SUMIFS($B$2:$B$381,$A$2:$A$381,J10)+SUMIFS($C$2:$C$381,$D$2:$D$381,J10) -> 0 | P10: =SUMIFS($C$2:$C$381,$A$2:$A$381,J10)+SUMIFS($B$2:$B$381,$D$2:$D$381,J10) -> 0 | Q10: =O10-P10 -> 0 | R10: =L10*3+M10 -> 0 | S10: =R10*1000000000+(Q10+1000)*100000+O10*100+11 -> 100000011 | T10: =(COUNTIFS($A$2:$A$191,J10,$E$2:$E$191,3)+COUNTIFS($D$2:$D$191,J10,$F$2:$F$191,3))*3+(COUNTIFS($A$2:$A$191,J10,$E$2:$E$191,1)+COUNTIFS($D$2:$D$191,J10,$F$2:$F$191,1)) -> 0 | U10: =(SUMIFS($B$2:$B$191,$A$2:$A$191,J10)+SUMIFS($C$2:$C$191,$D$2:$D$191,J10))-(SUMIFS($C$2:$C$191,$A$2:$A$191,J10)+SUMIFS($B$2:$B$191,$D$2:$D$191,J10)) -> 0 | V10: =SUMIFS($B$2:$B$191,$A$2:$A$191,J10)+SUMIFS($C$2:$C$191,$D$2:$D$191,J10) -> 0 | W10: =T10*1000000000+(U10+1000)*100000+V10*100+11 -> 100000011
A11: =Andata!D13 -> Venezia | B11: =IF(Andata!E13="","",Andata!E13) | C11: =IF(Andata!F13="","",Andata!F13) | D11: =Andata!G13 -> Lecce | E11: =IF(OR(B11="",C11=""),"",IF(B11>C11,3,IF(B11=C11,1,0))) | F11: =IF(OR(B11="",C11=""),"",IF(C11>B11,3,IF(B11=C11,1,0))) | G11: =IF(OR(B11="",C11=""),0,1) -> 0 | J11: Lazio | K11: =SUMIFS($G$2:$G$381,$A$2:$A$381,J11)+SUMIFS($G$2:$G$381,$D$2:$D$381,J11) -> 0 | L11: =COUNTIFS($A$2:$A$381,J11,$E$2:$E$381,3)+COUNTIFS($D$2:$D$381,J11,$F$2:$F$381,3) -> 0 | M11: =COUNTIFS($A$2:$A$381,J11,$E$2:$E$381,1)+COUNTIFS($D$2:$D$381,J11,$F$2:$F$381,1) -> 0 | N11: =COUNTIFS($A$2:$A$381,J11,$E$2:$E$381,0)+COUNTIFS($D$2:$D$381,J11,$F$2:$F$381,0) -> 0 | O11: =SUMIFS($B$2:$B$381,$A$2:$A$381,J11)+SUMIFS($C$2:$C$381,$D$2:$D$381,J11) -> 0 | P11: =SUMIFS($C$2:$C$381,$A$2:$A$381,J11)+SUMIFS($B$2:$B$381,$D$2:$D$381,J11) -> 0 | Q11: =O11-P11 -> 0 | R11: =L11*3+M11 -> 0 | S11: =R11*1000000000+(Q11+1000)*100000+O11*100+10 -> 100000010 | T11: =(COUNTIFS($A$2:$A$191,J11,$E$2:$E$191,3)+COUNTIFS($D$2:$D$191,J11,$F$2:$F$191,3))*3+(COUNTIFS($A$2:$A$191,J11,$E$2:$E$191,1)+COUNTIFS($D$2:$D$191,J11,$F$2:$F$191,1)) -> 0 | U11: =(SUMIFS($B$2:$B$191,$A$2:$A$191,J11)+SUMIFS($C$2:$C$191,$D$2:$D$191,J11))-(SUMIFS($C$2:$C$191,$A$2:$A$191,J11)+SUMIFS($B$2:$B$191,$D$2:$D$191,J11)) -> 0 | V11: =SUMIFS($B$2:$B$191,$A$2:$A$191,J11)+SUMIFS($C$2:$C$191,$D$2:$D$191,J11) -> 0 | W11: =T11*1000000000+(U11+1000)*100000+V11*100+10 -> 100000010
A12: =Andata!J4 -> Atalanta | B12: =IF(Andata!K4="","",Andata!K4) | C12: =IF(Andata!L4="","",Andata!L4) | D12: =Andata!M4 -> Bologna | E12: =IF(OR(B12="",C12=""),"",IF(B12>C12,3,IF(B12=C12,1,0))) | F12: =IF(OR(B12="",C12=""),"",IF(C12>B12,3,IF(B12=C12,1,0))) | G12: =IF(OR(B12="",C12=""),0,1) -> 0 | J12: Lecce | K12: =SUMIFS($G$2:$G$381,$A$2:$A$381,J12)+SUMIFS($G$2:$G$381,$D$2:$D$381,J12) -> 0 | L12: =COUNTIFS($A$2:$A$381,J12,$E$2:$E$381,3)+COUNTIFS($D$2:$D$381,J12,$F$2:$F$381,3) -> 0 | M12: =COUNTIFS($A$2:$A$381,J12,$E$2:$E$381,1)+COUNTIFS($D$2:$D$381,J12,$F$2:$F$381,1) -> 0 | N12: =COUNTIFS($A$2:$A$381,J12,$E$2:$E$381,0)+COUNTIFS($D$2:$D$381,J12,$F$2:$F$381,0) -> 0 | O12: =SUMIFS($B$2:$B$381,$A$2:$A$381,J12)+SUMIFS($C$2:$C$381,$D$2:$D$381,J12) -> 0 | P12: =SUMIFS($C$2:$C$381,$A$2:$A$381,J12)+SUMIFS($B$2:$B$381,$D$2:$D$381,J12) -> 0 | Q12: =O12-P12 -> 0 | R12: =L12*3+M12 -> 0 | S12: =R12*1000000000+(Q12+1000)*100000+O12*100+9 -> 100000009 | T12: =(COUNTIFS($A$2:$A$191,J12,$E$2:$E$191,3)+COUNTIFS($D$2:$D$191,J12,$F$2:$F$191,3))*3+(COUNTIFS($A$2:$A$191,J12,$E$2:$E$191,1)+COUNTIFS($D$2:$D$191,J12,$F$2:$F$191,1)) -> 0 | U12: =(SUMIFS($B$2:$B$191,$A$2:$A$191,J12)+SUMIFS($C$2:$C$191,$D$2:$D$191,J12))-(SUMIFS($C$2:$C$191,$A$2:$A$191,J12)+SUMIFS($B$2:$B$191,$D$2:$D$191,J12)) -> 0 | V12: =SUMIFS($B$2:$B$191,$A$2:$A$191,J12)+SUMIFS($C$2:$C$191,$D$2:$D$191,J12) -> 0 | W12: =T12*1000000000+(U12+1000)*100000+V12*100+9 -> 100000009
A13: =Andata!J5 -> Cagliari | B13: =IF(Andata!K5="","",Andata!K5) | C13: =IF(Andata!L5="","",Andata!L5) | D13: =Andata!M5 -> Inter | E13: =IF(OR(B13="",C13=""),"",IF(B13>C13,3,IF(B13=C13,1,0))) | F13: =IF(OR(B13="",C13=""),"",IF(C13>B13,3,IF(B13=C13,1,0))) | G13: =IF(OR(B13="",C13=""),0,1) -> 0 | J13: Milan | K13: =SUMIFS($G$2:$G$381,$A$2:$A$381,J13)+SUMIFS($G$2:$G$381,$D$2:$D$381,J13) -> 0 | L13: =COUNTIFS($A$2:$A$381,J13,$E$2:$E$381,3)+COUNTIFS($D$2:$D$381,J13,$F$2:$F$381,3) -> 0 | M13: =COUNTIFS($A$2:$A$381,J13,$E$2:$E$381,1)+COUNTIFS($D$2:$D$381,J13,$F$2:$F$381,1) -> 0 | N13: =COUNTIFS($A$2:$A$381,J13,$E$2:$E$381,0)+COUNTIFS($D$2:$D$381,J13,$F$2:$F$381,0) -> 0 | O13: =SUMIFS($B$2:$B$381,$A$2:$A$381,J13)+SUMIFS($C$2:$C$381,$D$2:$D$381,J13) -> 0 | P13: =SUMIFS($C$2:$C$381,$A$2:$A$381,J13)+SUMIFS($B$2:$B$381,$D$2:$D$381,J13) -> 0 | Q13: =O13-P13 -> 0 | R13: =L13*3+M13 -> 0 | S13: =R13*1000000000+(Q13+1000)*100000+O13*100+8 -> 100000008 | T13: =(COUNTIFS($A$2:$A$191,J13,$E$2:$E$191,3)+COUNTIFS($D$2:$D$191,J13,$F$2:$F$191,3))*3+(COUNTIFS($A$2:$A$191,J13,$E$2:$E$191,1)+COUNTIFS($D$2:$D$191,J13,$F$2:$F$191,1)) -> 0 | U13: =(SUMIFS($B$2:$B$191,$A$2:$A$191,J13)+SUMIFS($C$2:$C$191,$D$2:$D$191,J13))-(SUMIFS($C$2:$C$191,$A$2:$A$191,J13)+SUMIFS($B$2:$B$191,$D$2:$D$191,J13)) -> 0 | V13: =SUMIFS($B$2:$B$191,$A$2:$A$191,J13)+SUMIFS($C$2:$C$191,$D$2:$D$191,J13) -> 0 | W13: =T13*1000000000+(U13+1000)*100000+V13*100+8 -> 100000008
A14: =Andata!J6 -> Fiorentina | B14: =IF(Andata!K6="","",Andata!K6) | C14: =IF(Andata!L6="","",Andata!L6) | D14: =Andata!M6 -> Frosinone | E14: =IF(OR(B14="",C14=""),"",IF(B14>C14,3,IF(B14=C14,1,0))) | F14: =IF(OR(B14="",C14=""),"",IF(C14>B14,3,IF(B14=C14,1,0))) | G14: =IF(OR(B14="",C14=""),0,1) -> 0 | J14: Monza | K14: =SUMIFS($G$2:$G$381,$A$2:$A$381,J14)+SUMIFS($G$2:$G$381,$D$2:$D$381,J14) -> 0 | L14: =COUNTIFS($A$2:$A$381,J14,$E$2:$E$381,3)+COUNTIFS($D$2:$D$381,J14,$F$2:$F$381,3) -> 0 | M14: =COUNTIFS($A$2:$A$381,J14,$E$2:$E$381,1)+COUNTIFS($D$2:$D$381,J14,$F$2:$F$381,1) -> 0 | N14: =COUNTIFS($A$2:$A$381,J14,$E$2:$E$381,0)+COUNTIFS($D$2:$D$381,J14,$F$2:$F$381,0) -> 0 | O14: =SUMIFS($B$2:$B$381,$A$2:$A$381,J14)+SUMIFS($C$2:$C$381,$D$2:$D$381,J14) -> 0 | P14: =SUMIFS($C$2:$C$381,$A$2:$A$381,J14)+SUMIFS($B$2:$B$381,$D$2:$D$381,J14) -> 0 | Q14: =O14-P14 -> 0 | R14: =L14*3+M14 -> 0 | S14: =R14*1000000000+(Q14+1000)*100000+O14*100+7 -> 100000007 | T14: =(COUNTIFS($A$2:$A$191,J14,$E$2:$E$191,3)+COUNTIFS($D$2:$D$191,J14,$F$2:$F$191,3))*3+(COUNTIFS($A$2:$A$191,J14,$E$2:$E$191,1)+COUNTIFS($D$2:$D$191,J14,$F$2:$F$191,1)) -> 0 | U14: =(SUMIFS($B$2:$B$191,$A$2:$A$191,J14)+SUMIFS($C$2:$C$191,$D$2:$D$191,J14))-(SUMIFS($C$2:$C$191,$A$2:$A$191,J14)+SUMIFS($B$2:$B$191,$D$2:$D$191,J14)) -> 0 | V14: =SUMIFS($B$2:$B$191,$A$2:$A$191,J14)+SUMIFS($C$2:$C$191,$D$2:$D$191,J14) -> 0 | W14: =T14*1000000000+(U14+1000)*100000+V14*100+7 -> 100000007
A15: =Andata!J7 -> Juventus | B15: =IF(Andata!K7="","",Andata!K7) | C15: =IF(Andata!L7="","",Andata!L7) | D15: =Andata!M7 -> Parma | E15: =IF(OR(B15="",C15=""),"",IF(B15>C15,3,IF(B15=C15,1,0))) | F15: =IF(OR(B15="",C15=""),"",IF(C15>B15,3,IF(B15=C15,1,0))) | G15: =IF(OR(B15="",C15=""),0,1) -> 0 | J15: Napoli | K15: =SUMIFS($G$2:$G$381,$A$2:$A$381,J15)+SUMIFS($G$2:$G$381,$D$2:$D$381,J15) -> 0 | L15: =COUNTIFS($A$2:$A$381,J15,$E$2:$E$381,3)+COUNTIFS($D$2:$D$381,J15,$F$2:$F$381,3) -> 0 | M15: =COUNTIFS($A$2:$A$381,J15,$E$2:$E$381,1)+COUNTIFS($D$2:$D$381,J15,$F$2:$F$381,1) -> 0 | N15: =COUNTIFS($A$2:$A$381,J15,$E$2:$E$381,0)+COUNTIFS($D$2:$D$381,J15,$F$2:$F$381,0) -> 0 | O15: =SUMIFS($B$2:$B$381,$A$2:$A$381,J15)+SUMIFS($C$2:$C$381,$D$2:$D$381,J15) -> 0 | P15: =SUMIFS($C$2:$C$381,$A$2:$A$381,J15)+SUMIFS($B$2:$B$381,$D$2:$D$381,J15) -> 0 | Q15: =O15-P15 -> 0 | R15: =L15*3+M15 -> 0 | S15: =R15*1000000000+(Q15+1000)*100000+O15*100+6 -> 100000006 | T15: =(COUNTIFS($A$2:$A$191,J15,$E$2:$E$191,3)+COUNTIFS($D$2:$D$191,J15,$F$2:$F$191,3))*3+(COUNTIFS($A$2:$A$191,J15,$E$2:$E$191,1)+COUNTIFS($D$2:$D$191,J15,$F$2:$F$191,1)) -> 0 | U15: =(SUMIFS($B$2:$B$191,$A$2:$A$191,J15)+SUMIFS($C$2:$C$191,$D$2:$D$191,J15))-(SUMIFS($C$2:$C$191,$A$2:$A$191,J15)+SUMIFS($B$2:$B$191,$D$2:$D$191,J15)) -> 0 | V15: =SUMIFS($B$2:$B$191,$A$2:$A$191,J15)+SUMIFS($C$2:$C$191,$D$2:$D$191,J15) -> 0 | W15: =T15*1000000000+(U15+1000)*100000+V15*100+6 -> 100000006
A16: =Andata!J8 -> Lazio | B16: =IF(Andata!K8="","",Andata!K8) | C16: =IF(Andata!L8="","",Andata!L8) | D16: =Andata!M8 -> Genoa | E16: =IF(OR(B16="",C16=""),"",IF(B16>C16,3,IF(B16=C16,1,0))) | F16: =IF(OR(B16="",C16=""),"",IF(C16>B16,3,IF(B16=C16,1,0))) | G16: =IF(OR(B16="",C16=""),0,1) -> 0 | J16: Parma | K16: =SUMIFS($G$2:$G$381,$A$2:$A$381,J16)+SUMIFS($G$2:$G$381,$D$2:$D$381,J16) -> 0 | L16: =COUNTIFS($A$2:$A$381,J16,$E$2:$E$381,3)+COUNTIFS($D$2:$D$381,J16,$F$2:$F$381,3) -> 0 | M16: =COUNTIFS($A$2:$A$381,J16,$E$2:$E$381,1)+COUNTIFS($D$2:$D$381,J16,$F$2:$F$381,1) -> 0 | N16: =COUNTIFS($A$2:$A$381,J16,$E$2:$E$381,0)+COUNTIFS($D$2:$D$381,J16,$F$2:$F$381,0) -> 0 | O16: =SUMIFS($B$2:$B$381,$A$2:$A$381,J16)+SUMIFS($C$2:$C$381,$D$2:$D$381,J16) -> 0 | P16: =SUMIFS($C$2:$C$381,$A$2:$A$381,J16)+SUMIFS($B$2:$B$381,$D$2:$D$381,J16) -> 0 | Q16: =O16-P16 -> 0 | R16: =L16*3+M16 -> 0 | S16: =R16*1000000000+(Q16+1000)*100000+O16*100+5 -> 100000005 | T16: =(COUNTIFS($A$2:$A$191,J16,$E$2:$E$191,3)+COUNTIFS($D$2:$D$191,J16,$F$2:$F$191,3))*3+(COUNTIFS($A$2:$A$191,J16,$E$2:$E$191,1)+COUNTIFS($D$2:$D$191,J16,$F$2:$F$191,1)) -> 0 | U16: =(SUMIFS($B$2:$B$191,$A$2:$A$191,J16)+SUMIFS($C$2:$C$191,$D$2:$D$191,J16))-(SUMIFS($C$2:$C$191,$A$2:$A$191,J16)+SUMIFS($B$2:$B$191,$D$2:$D$191,J16)) -> 0 | V16: =SUMIFS($B$2:$B$191,$A$2:$A$191,J16)+SUMIFS($C$2:$C$191,$D$2:$D$191,J16) -> 0 | W16: =T16*1000000000+(U16+1000)*100000+V16*100+5 -> 100000005
A17: =Andata!J9 -> Lecce | B17: =IF(Andata!K9="","",Andata!K9) | C17: =IF(Andata!L9="","",Andata!L9) | D17: =Andata!M9 -> Roma | E17: =IF(OR(B17="",C17=""),"",IF(B17>C17,3,IF(B17=C17,1,0))) | F17: =IF(OR(B17="",C17=""),"",IF(C17>B17,3,IF(B17=C17,1,0))) | G17: =IF(OR(B17="",C17=""),0,1) -> 0 | J17: Roma | K17: =SUMIFS($G$2:$G$381,$A$2:$A$381,J17)+SUMIFS($G$2:$G$381,$D$2:$D$381,J17) -> 0 | L17: =COUNTIFS($A$2:$A$381,J17,$E$2:$E$381,3)+COUNTIFS($D$2:$D$381,J17,$F$2:$F$381,3) -> 0 | M17: =COUNTIFS($A$2:$A$381,J17,$E$2:$E$381,1)+COUNTIFS($D$2:$D$381,J17,$F$2:$F$381,1) -> 0 | N17: =COUNTIFS($A$2:$A$381,J17,$E$2:$E$381,0)+COUNTIFS($D$2:$D$381,J17,$F$2:$F$381,0) -> 0 | O17: =SUMIFS($B$2:$B$381,$A$2:$A$381,J17)+SUMIFS($C$2:$C$381,$D$2:$D$381,J17) -> 0 | P17: =SUMIFS($C$2:$C$381,$A$2:$A$381,J17)+SUMIFS($B$2:$B$381,$D$2:$D$381,J17) -> 0 | Q17: =O17-P17 -> 0 | R17: =L17*3+M17 -> 0 | S17: =R17*1000000000+(Q17+1000)*100000+O17*100+4 -> 100000004 | T17: =(COUNTIFS($A$2:$A$191,J17,$E$2:$E$191,3)+COUNTIFS($D$2:$D$191,J17,$F$2:$F$191,3))*3+(COUNTIFS($A$2:$A$191,J17,$E$2:$E$191,1)+COUNTIFS($D$2:$D$191,J17,$F$2:$F$191,1)) -> 0 | U17: =(SUMIFS($B$2:$B$191,$A$2:$A$191,J17)+SUMIFS($C$2:$C$191,$D$2:$D$191,J17))-(SUMIFS($C$2:$C$191,$A$2:$A$191,J17)+SUMIFS($B$2:$B$191,$D$2:$D$191,J17)) -> 0 | V17: =SUMIFS($B$2:$B$191,$A$2:$A$191,J17)+SUMIFS($C$2:$C$191,$D$2:$D$191,J17) -> 0 | W17: =T17*1000000000+(U17+1000)*100000+V17*100+4 -> 100000004
A18: =Andata!J10 -> Milan | B18: =IF(Andata!K10="","",Andata!K10) | C18: =IF(Andata!L10="","",Andata!L10) | D18: =Andata!M10 -> Venezia | E18: =IF(OR(B18="",C18=""),"",IF(B18>C18,3,IF(B18=C18,1,0))) | F18: =IF(OR(B18="",C18=""),"",IF(C18>B18,3,IF(B18=C18,1,0))) | G18: =IF(OR(B18="",C18=""),0,1) -> 0 | J18: Sassuolo | K18: =SUMIFS($G$2:$G$381,$A$2:$A$381,J18)+SUMIFS($G$2:$G$381,$D$2:$D$381,J18) -> 0 | L18: =COUNTIFS($A$2:$A$381,J18,$E$2:$E$381,3)+COUNTIFS($D$2:$D$381,J18,$F$2:$F$381,3) -> 0 | M18: =COUNTIFS($A$2:$A$381,J18,$E$2:$E$381,1)+COUNTIFS($D$2:$D$381,J18,$F$2:$F$381,1) -> 0 | N18: =COUNTIFS($A$2:$A$381,J18,$E$2:$E$381,0)+COUNTIFS($D$2:$D$381,J18,$F$2:$F$381,0) -> 0 | O18: =SUMIFS($B$2:$B$381,$A$2:$A$381,J18)+SUMIFS($C$2:$C$381,$D$2:$D$381,J18) -> 0 | P18: =SUMIFS($C$2:$C$381,$A$2:$A$381,J18)+SUMIFS($B$2:$B$381,$D$2:$D$381,J18) -> 0 | Q18: =O18-P18 -> 0 | R18: =L18*3+M18 -> 0 | S18: =R18*1000000000+(Q18+1000)*100000+O18*100+3 -> 100000003 | T18: =(COUNTIFS($A$2:$A$191,J18,$E$2:$E$191,3)+COUNTIFS($D$2:$D$191,J18,$F$2:$F$191,3))*3+(COUNTIFS($A$2:$A$191,J18,$E$2:$E$191,1)+COUNTIFS($D$2:$D$191,J18,$F$2:$F$191,1)) -> 0 | U18: =(SUMIFS($B$2:$B$191,$A$2:$A$191,J18)+SUMIFS($C$2:$C$191,$D$2:$D$191,J18))-(SUMIFS($C$2:$C$191,$A$2:$A$191,J18)+SUMIFS($B$2:$B$191,$D$2:$D$191,J18)) -> 0 | V18: =SUMIFS($B$2:$B$191,$A$2:$A$191,J18)+SUMIFS($C$2:$C$191,$D$2:$D$191,J18) -> 0 | W18: =T18*1000000000+(U18+1000)*100000+V18*100+3 -> 100000003
A19: =Andata!J11 -> Monza | B19: =IF(Andata!K11="","",Andata!K11) | C19: =IF(Andata!L11="","",Andata!L11) | D19: =Andata!M11 -> Udinese | E19: =IF(OR(B19="",C19=""),"",IF(B19>C19,3,IF(B19=C19,1,0))) | F19: =IF(OR(B19="",C19=""),"",IF(C19>B19,3,IF(B19=C19,1,0))) | G19: =IF(OR(B19="",C19=""),0,1) -> 0 | J19: Torino | K19: =SUMIFS($G$2:$G$381,$A$2:$A$381,J19)+SUMIFS($G$2:$G$381,$D$2:$D$381,J19) -> 0 | L19: =COUNTIFS($A$2:$A$381,J19,$E$2:$E$381,3)+COUNTIFS($D$2:$D$381,J19,$F$2:$F$381,3) -> 0 | M19: =COUNTIFS($A$2:$A$381,J19,$E$2:$E$381,1)+COUNTIFS($D$2:$D$381,J19,$F$2:$F$381,1) -> 0 | N19: =COUNTIFS($A$2:$A$381,J19,$E$2:$E$381,0)+COUNTIFS($D$2:$D$381,J19,$F$2:$F$381,0) -> 0 | O19: =SUMIFS($B$2:$B$381,$A$2:$A$381,J19)+SUMIFS($C$2:$C$381,$D$2:$D$381,J19) -> 0 | P19: =SUMIFS($C$2:$C$381,$A$2:$A$381,J19)+SUMIFS($B$2:$B$381,$D$2:$D$381,J19) -> 0 | Q19: =O19-P19 -> 0 | R19: =L19*3+M19 -> 0 | S19: =R19*1000000000+(Q19+1000)*100000+O19*100+2 -> 100000002 | T19: =(COUNTIFS($A$2:$A$191,J19,$E$2:$E$191,3)+COUNTIFS($D$2:$D$191,J19,$F$2:$F$191,3))*3+(COUNTIFS($A$2:$A$191,J19,$E$2:$E$191,1)+COUNTIFS($D$2:$D$191,J19,$F$2:$F$191,1)) -> 0 | U19: =(SUMIFS($B$2:$B$191,$A$2:$A$191,J19)+SUMIFS($C$2:$C$191,$D$2:$D$191,J19))-(SUMIFS($C$2:$C$191,$A$2:$A$191,J19)+SUMIFS($B$2:$B$191,$D$2:$D$191,J19)) -> 0 | V19: =SUMIFS($B$2:$B$191,$A$2:$A$191,J19)+SUMIFS($C$2:$C$191,$D$2:$D$191,J19) -> 0 | W19: =T19*1000000000+(U19+1000)*100000+V19*100+2 -> 100000002
A20: =Andata!J12 -> Napoli | B20: =IF(Andata!K12="","",Andata!K12) | C20: =IF(Andata!L12="","",Andata!L12) | D20: =Andata!M12 -> Como | E20: =IF(OR(B20="",C20=""),"",IF(B20>C20,3,IF(B20=C20,1,0))) | F20: =IF(OR(B20="",C20=""),"",IF(C20>B20,3,IF(B20=C20,1,0))) | G20: =IF(OR(B20="",C20=""),0,1) -> 0 | J20: Udinese | K20: =SUMIFS($G$2:$G$381,$A$2:$A$381,J20)+SUMIFS($G$2:$G$381,$D$2:$D$381,J20) -> 0 | L20: =COUNTIFS($A$2:$A$381,J20,$E$2:$E$381,3)+COUNTIFS($D$2:$D$381,J20,$F$2:$F$381,3) -> 0 | M20: =COUNTIFS($A$2:$A$381,J20,$E$2:$E$381,1)+COUNTIFS($D$2:$D$381,J20,$F$2:$F$381,1) -> 0 | N20: =COUNTIFS($A$2:$A$381,J20,$E$2:$E$381,0)+COUNTIFS($D$2:$D$381,J20,$F$2:$F$381,0) -> 0 | O20: =SUMIFS($B$2:$B$381,$A$2:$A$381,J20)+SUMIFS($C$2:$C$381,$D$2:$D$381,J20) -> 0 | P20: =SUMIFS($C$2:$C$381,$A$2:$A$381,J20)+SUMIFS($B$2:$B$381,$D$2:$D$381,J20) -> 0 | Q20: =O20-P20 -> 0 | R20: =L20*3+M20 -> 0 | S20: =R20*1000000000+(Q20+1000)*100000+O20*100+1 -> 100000001 | T20: =(COUNTIFS($A$2:$A$191,J20,$E$2:$E$191,3)+COUNTIFS($D$2:$D$191,J20,$F$2:$F$191,3))*3+(COUNTIFS($A$2:$A$191,J20,$E$2:$E$191,1)+COUNTIFS($D$2:$D$191,J20,$F$2:$F$191,1)) -> 0 | U20: =(SUMIFS($B$2:$B$191,$A$2:$A$191,J20)+SUMIFS($C$2:$C$191,$D$2:$D$191,J20))-(SUMIFS($C$2:$C$191,$A$2:$A$191,J20)+SUMIFS($B$2:$B$191,$D$2:$D$191,J20)) -> 0 | V20: =SUMIFS($B$2:$B$191,$A$2:$A$191,J20)+SUMIFS($C$2:$C$191,$D$2:$D$191,J20) -> 0 | W20: =T20*1000000000+(U20+1000)*100000+V20*100+1 -> 100000001
A21: =Andata!J13 -> Sassuolo | B21: =IF(Andata!K13="","",Andata!K13) | C21: =IF(Andata!L13="","",Andata!L13) | D21: =Andata!M13 -> Torino | E21: =IF(OR(B21="",C21=""),"",IF(B21>C21,3,IF(B21=C21,1,0))) | F21: =IF(OR(B21="",C21=""),"",IF(C21>B21,3,IF(B21=C21,1,0))) | G21: =IF(OR(B21="",C21=""),0,1) -> 0 | J21: Venezia | K21: =SUMIFS($G$2:$G$381,$A$2:$A$381,J21)+SUMIFS($G$2:$G$381,$D$2:$D$381,J21) -> 0 | L21: =COUNTIFS($A$2:$A$381,J21,$E$2:$E$381,3)+COUNTIFS($D$2:$D$381,J21,$F$2:$F$381,3) -> 0 | M21: =COUNTIFS($A$2:$A$381,J21,$E$2:$E$381,1)+COUNTIFS($D$2:$D$381,J21,$F$2:$F$381,1) -> 0 | N21: =COUNTIFS($A$2:$A$381,J21,$E$2:$E$381,0)+COUNTIFS($D$2:$D$381,J21,$F$2:$F$381,0) -> 0 | O21: =SUMIFS($B$2:$B$381,$A$2:$A$381,J21)+SUMIFS($C$2:$C$381,$D$2:$D$381,J21) -> 0 | P21: =SUMIFS($C$2:$C$381,$A$2:$A$381,J21)+SUMIFS($B$2:$B$381,$D$2:$D$381,J21) -> 0 | Q21: =O21-P21 -> 0 | R21: =L21*3+M21 -> 0 | S21: =R21*1000000000+(Q21+1000)*100000+O21*100+0 -> 100000000 | T21: =(COUNTIFS($A$2:$A$191,J21,$E$2:$E$191,3)+COUNTIFS($D$2:$D$191,J21,$F$2:$F$191,3))*3+(COUNTIFS($A$2:$A$191,J21,$E$2:$E$191,1)+COUNTIFS($D$2:$D$191,J21,$F$2:$F$191,1)) -> 0 | U21: =(SUMIFS($B$2:$B$191,$A$2:$A$191,J21)+SUMIFS($C$2:$C$191,$D$2:$D$191,J21))-(SUMIFS($C$2:$C$191,$A$2:$A$191,J21)+SUMIFS($B$2:$B$191,$D$2:$D$191,J21)) -> 0 | V21: =SUMIFS($B$2:$B$191,$A$2:$A$191,J21)+SUMIFS($C$2:$C$191,$D$2:$D$191,J21) -> 0 | W21: =T21*1000000000+(U21+1000)*100000+V21*100+0 -> 100000000
A22: =Andata!P4 -> Bologna | B22: =IF(Andata!Q4="","",Andata!Q4) | C22: =IF(Andata!R4="","",Andata!R4) | D22: =Andata!S4 -> Sassuolo | E22: =IF(OR(B22="",C22=""),"",IF(B22>C22,3,IF(B22=C22,1,0))) | F22: =IF(OR(B22="",C22=""),"",IF(C22>B22,3,IF(B22=C22,1,0))) | G22: =IF(OR(B22="",C22=""),0,1) -> 0
A23: =Andata!P5 -> Cagliari | B23: =IF(Andata!Q5="","",Andata!Q5) | C23: =IF(Andata!R5="","",Andata!R5) | D23: =Andata!S5 -> Lecce | E23: =IF(OR(B23="",C23=""),"",IF(B23>C23,3,IF(B23=C23,1,0))) | F23: =IF(OR(B23="",C23=""),"",IF(C23>B23,3,IF(B23=C23,1,0))) | G23: =IF(OR(B23="",C23=""),0,1) -> 0
A24: =Andata!P6 -> Fiorentina | B24: =IF(Andata!Q6="","",Andata!Q6) | C24: =IF(Andata!R6="","",Andata!R6) | D24: =Andata!S6 -> Torino | E24: =IF(OR(B24="",C24=""),"",IF(B24>C24,3,IF(B24=C24,1,0))) | F24: =IF(OR(B24="",C24=""),"",IF(C24>B24,3,IF(B24=C24,1,0))) | G24: =IF(OR(B24="",C24=""),0,1) -> 0
A25: =Andata!P7 -> Frosinone | B25: =IF(Andata!Q7="","",Andata!Q7) | C25: =IF(Andata!R7="","",Andata!R7) | D25: =Andata!S7 -> Venezia | E25: =IF(OR(B25="",C25=""),"",IF(B25>C25,3,IF(B25=C25,1,0))) | F25: =IF(OR(B25="",C25=""),"",IF(C25>B25,3,IF(B25=C25,1,0))) | G25: =IF(OR(B25="",C25=""),0,1) -> 0
A26: =Andata!P8 -> Genoa | B26: =IF(Andata!Q8="","",Andata!Q8) | C26: =IF(Andata!R8="","",Andata!R8) | D26: =Andata!S8 -> Como | E26: =IF(OR(B26="",C26=""),"",IF(B26>C26,3,IF(B26=C26,1,0))) | F26: =IF(OR(B26="",C26=""),"",IF(C26>B26,3,IF(B26=C26,1,0))) | G26: =IF(OR(B26="",C26=""),0,1) -> 0
A27: =Andata!P9 -> Inter | B27: =IF(Andata!Q9="","",Andata!Q9) | C27: =IF(Andata!R9="","",Andata!R9) | D27: =Andata!S9 -> Napoli | E27: =IF(OR(B27="",C27=""),"",IF(B27>C27,3,IF(B27=C27,1,0))) | F27: =IF(OR(B27="",C27=""),"",IF(C27>B27,3,IF(B27=C27,1,0))) | G27: =IF(OR(B27="",C27=""),0,1) -> 0
A28: =Andata!P10 -> Juventus | B28: =IF(Andata!Q10="","",Andata!Q10) | C28: =IF(Andata!R10="","",Andata!R10) | D28: =Andata!S10 -> Milan | E28: =IF(OR(B28="",C28=""),"",IF(B28>C28,3,IF(B28=C28,1,0))) | F28: =IF(OR(B28="",C28=""),"",IF(C28>B28,3,IF(B28=C28,1,0))) | G28: =IF(OR(B28="",C28=""),0,1) -> 0
A29: =Andata!P11 -> Parma | B29: =IF(Andata!Q11="","",Andata!Q11) | C29: =IF(Andata!R11="","",Andata!R11) | D29: =Andata!S11 -> Monza | E29: =IF(OR(B29="",C29=""),"",IF(B29>C29,3,IF(B29=C29,1,0))) | F29: =IF(OR(B29="",C29=""),"",IF(C29>B29,3,IF(B29=C29,1,0))) | G29: =IF(OR(B29="",C29=""),0,1) -> 0
A30: =Andata!P12 -> Roma | B30: =IF(Andata!Q12="","",Andata!Q12) | C30: =IF(Andata!R12="","",Andata!R12) | D30: =Andata!S12 -> Atalanta | E30: =IF(OR(B30="",C30=""),"",IF(B30>C30,3,IF(B30=C30,1,0))) | F30: =IF(OR(B30="",C30=""),"",IF(C30>B30,3,IF(B30=C30,1,0))) | G30: =IF(OR(B30="",C30=""),0,1) -> 0
A31: =Andata!P13 -> Udinese | B31: =IF(Andata!Q13="","",Andata!Q13) | C31: =IF(Andata!R13="","",Andata!R13) | D31: =Andata!S13 -> Lazio | E31: =IF(OR(B31="",C31=""),"",IF(B31>C31,3,IF(B31=C31,1,0))) | F31: =IF(OR(B31="",C31=""),"",IF(C31>B31,3,IF(B31=C31,1,0))) | G31: =IF(OR(B31="",C31=""),0,1) -> 0
A32: =Andata!V4 -> Atalanta | B32: =IF(Andata!W4="","",Andata!W4) | C32: =IF(Andata!X4="","",Andata!X4) | D32: =Andata!Y4 -> Cagliari | E32: =IF(OR(B32="",C32=""),"",IF(B32>C32,3,IF(B32=C32,1,0))) | F32: =IF(OR(B32="",C32=""),"",IF(C32>B32,3,IF(B32=C32,1,0))) | G32: =IF(OR(B32="",C32=""),0,1) -> 0
A33: =Andata!V5 -> Como | B33: =IF(Andata!W5="","",Andata!W5) | C33: =IF(Andata!X5="","",Andata!X5) | D33: =Andata!Y5 -> Parma | E33: =IF(OR(B33="",C33=""),"",IF(B33>C33,3,IF(B33=C33,1,0))) | F33: =IF(OR(B33="",C33=""),"",IF(C33>B33,3,IF(B33=C33,1,0))) | G33: =IF(OR(B33="",C33=""),0,1) -> 0
A34: =Andata!V6 -> Genoa | B34: =IF(Andata!W6="","",Andata!W6) | C34: =IF(Andata!X6="","",Andata!X6) | D34: =Andata!Y6 -> Frosinone | E34: =IF(OR(B34="",C34=""),"",IF(B34>C34,3,IF(B34=C34,1,0))) | F34: =IF(OR(B34="",C34=""),"",IF(C34>B34,3,IF(B34=C34,1,0))) | G34: =IF(OR(B34="",C34=""),0,1) -> 0
A35: =Andata!V7 -> Inter | B35: =IF(Andata!W7="","",Andata!W7) | C35: =IF(Andata!X7="","",Andata!X7) | D35: =Andata!Y7 -> Udinese | E35: =IF(OR(B35="",C35=""),"",IF(B35>C35,3,IF(B35=C35,1,0))) | F35: =IF(OR(B35="",C35=""),"",IF(C35>B35,3,IF(B35=C35,1,0))) | G35: =IF(OR(B35="",C35=""),0,1) -> 0
A36: =Andata!V8 -> Lazio | B36: =IF(Andata!W8="","",Andata!W8) | C36: =IF(Andata!X8="","",Andata!X8) | D36: =Andata!Y8 -> Milan | E36: =IF(OR(B36="",C36=""),"",IF(B36>C36,3,IF(B36=C36,1,0))) | F36: =IF(OR(B36="",C36=""),"",IF(C36>B36,3,IF(B36=C36,1,0))) | G36: =IF(OR(B36="",C36=""),0,1) -> 0
A37: =Andata!V9 -> Lecce | B37: =IF(Andata!W9="","",Andata!W9) | C37: =IF(Andata!X9="","",Andata!X9) | D37: =Andata!Y9 -> Monza | E37: =IF(OR(B37="",C37=""),"",IF(B37>C37,3,IF(B37=C37,1,0))) | F37: =IF(OR(B37="",C37=""),"",IF(C37>B37,3,IF(B37=C37,1,0))) | G37: =IF(OR(B37="",C37=""),0,1) -> 0
A38: =Andata!V10 -> Napoli | B38: =IF(Andata!W10="","",Andata!W10) | C38: =IF(Andata!X10="","",Andata!X10) | D38: =Andata!Y10 -> Bologna | E38: =IF(OR(B38="",C38=""),"",IF(B38>C38,3,IF(B38=C38,1,0))) | F38: =IF(OR(B38="",C38=""),"",IF(C38>B38,3,IF(B38=C38,1,0))) | G38: =IF(OR(B38="",C38=""),0,1) -> 0
A39: =Andata!V11 -> Sassuolo | B39: =IF(Andata!W11="","",Andata!W11) | C39: =IF(Andata!X11="","",Andata!X11) | D39: =Andata!Y11 -> Juventus | E39: =IF(OR(B39="",C39=""),"",IF(B39>C39,3,IF(B39=C39,1,0))) | F39: =IF(OR(B39="",C39=""),"",IF(C39>B39,3,IF(B39=C39,1,0))) | G39: =IF(OR(B39="",C39=""),0,1) -> 0
A40: =Andata!V12 -> Torino | B40: =IF(Andata!W12="","",Andata!W12) | C40: =IF(Andata!X12="","",Andata!X12) | D40: =Andata!Y12 -> Roma | E40: =IF(OR(B40="",C40=""),"",IF(B40>C40,3,IF(B40=C40,1,0))) | F40: =IF(OR(B40="",C40=""),"",IF(C40>B40,3,IF(B40=C40,1,0))) | G40: =IF(OR(B40="",C40=""),0,1) -> 0
...
